================================================================================
load tweets
================================================================================
Traceback (most recent call last):
  File "/home/mynguyen/.local/lib/python3.6/site-packages/sqlalchemy/engine/base.py", line 3371, in _wrap_pool_connect
    return fn()
  File "/home/mynguyen/.local/lib/python3.6/site-packages/sqlalchemy/pool/base.py", line 327, in connect
    return _ConnectionFairy._checkout(self)
  File "/home/mynguyen/.local/lib/python3.6/site-packages/sqlalchemy/pool/base.py", line 894, in _checkout
    fairy = _ConnectionRecord.checkout(pool)
  File "/home/mynguyen/.local/lib/python3.6/site-packages/sqlalchemy/pool/base.py", line 493, in checkout
    rec = pool._do_get()
  File "/home/mynguyen/.local/lib/python3.6/site-packages/sqlalchemy/pool/impl.py", line 146, in _do_get
    self._dec_overflow()
  File "/home/mynguyen/.local/lib/python3.6/site-packages/sqlalchemy/util/langhelpers.py", line 72, in __exit__
    with_traceback=exc_tb,
  File "/home/mynguyen/.local/lib/python3.6/site-packages/sqlalchemy/util/compat.py", line 211, in raise_
    raise exception
  File "/home/mynguyen/.local/lib/python3.6/site-packages/sqlalchemy/pool/impl.py", line 143, in _do_get
    return self._create_connection()
  File "/home/mynguyen/.local/lib/python3.6/site-packages/sqlalchemy/pool/base.py", line 273, in _create_connection
    return _ConnectionRecord(self)
  File "/home/mynguyen/.local/lib/python3.6/site-packages/sqlalchemy/pool/base.py", line 388, in __init__
    self.__connect()
  File "/home/mynguyen/.local/lib/python3.6/site-packages/sqlalchemy/pool/base.py", line 691, in __connect
    pool.logger.debug("Error on connect(): %s", e)
  File "/home/mynguyen/.local/lib/python3.6/site-packages/sqlalchemy/util/langhelpers.py", line 72, in __exit__
    with_traceback=exc_tb,
  File "/home/mynguyen/.local/lib/python3.6/site-packages/sqlalchemy/util/compat.py", line 211, in raise_
    raise exception
  File "/home/mynguyen/.local/lib/python3.6/site-packages/sqlalchemy/pool/base.py", line 686, in __connect
    self.dbapi_connection = connection = pool._invoke_creator(self)
  File "/home/mynguyen/.local/lib/python3.6/site-packages/sqlalchemy/engine/create.py", line 574, in connect
    return dialect.connect(*cargs, **cparams)
  File "/home/mynguyen/.local/lib/python3.6/site-packages/sqlalchemy/engine/default.py", line 598, in connect
    return self.dbapi.connect(*cargs, **cparams)
  File "/home/mynguyen/.local/lib/python3.6/site-packages/psycopg2/__init__.py", line 122, in connect
    conn = _connect(dsn, connection_factory=connection_factory, **kwasync)
psycopg2.OperationalError: could not connect to server: Connection refused
	Is the server running on host "localhost" (127.0.0.1) and accepting
	TCP/IP connections on port 13490?


The above exception was the direct cause of the following exception:

Traceback (most recent call last):
  File "load_tweets.py", line 345, in <module>
    connection = engine.connect()
  File "/home/mynguyen/.local/lib/python3.6/site-packages/sqlalchemy/engine/base.py", line 3325, in connect
    return self._connection_cls(self, close_with_result=close_with_result)
  File "/home/mynguyen/.local/lib/python3.6/site-packages/sqlalchemy/engine/base.py", line 96, in __init__
    else engine.raw_connection()
  File "/home/mynguyen/.local/lib/python3.6/site-packages/sqlalchemy/engine/base.py", line 3404, in raw_connection
    return self._wrap_pool_connect(self.pool.connect, _connection)
  File "/home/mynguyen/.local/lib/python3.6/site-packages/sqlalchemy/engine/base.py", line 3375, in _wrap_pool_connect
    e, dialect, self
  File "/home/mynguyen/.local/lib/python3.6/site-packages/sqlalchemy/engine/base.py", line 2209, in _handle_dbapi_exception_noconnection
    sqlalchemy_exception, with_traceback=exc_info[2], from_=e
  File "/home/mynguyen/.local/lib/python3.6/site-packages/sqlalchemy/util/compat.py", line 211, in raise_
    raise exception
  File "/home/mynguyen/.local/lib/python3.6/site-packages/sqlalchemy/engine/base.py", line 3371, in _wrap_pool_connect
    return fn()
  File "/home/mynguyen/.local/lib/python3.6/site-packages/sqlalchemy/pool/base.py", line 327, in connect
    return _ConnectionFairy._checkout(self)
  File "/home/mynguyen/.local/lib/python3.6/site-packages/sqlalchemy/pool/base.py", line 894, in _checkout
    fairy = _ConnectionRecord.checkout(pool)
  File "/home/mynguyen/.local/lib/python3.6/site-packages/sqlalchemy/pool/base.py", line 493, in checkout
    rec = pool._do_get()
  File "/home/mynguyen/.local/lib/python3.6/site-packages/sqlalchemy/pool/impl.py", line 146, in _do_get
    self._dec_overflow()
  File "/home/mynguyen/.local/lib/python3.6/site-packages/sqlalchemy/util/langhelpers.py", line 72, in __exit__
    with_traceback=exc_tb,
  File "/home/mynguyen/.local/lib/python3.6/site-packages/sqlalchemy/util/compat.py", line 211, in raise_
    raise exception
  File "/home/mynguyen/.local/lib/python3.6/site-packages/sqlalchemy/pool/impl.py", line 143, in _do_get
    return self._create_connection()
  File "/home/mynguyen/.local/lib/python3.6/site-packages/sqlalchemy/pool/base.py", line 273, in _create_connection
    return _ConnectionRecord(self)
  File "/home/mynguyen/.local/lib/python3.6/site-packages/sqlalchemy/pool/base.py", line 388, in __init__
    self.__connect()
  File "/home/mynguyen/.local/lib/python3.6/site-packages/sqlalchemy/pool/base.py", line 691, in __connect
    pool.logger.debug("Error on connect(): %s", e)
  File "/home/mynguyen/.local/lib/python3.6/site-packages/sqlalchemy/util/langhelpers.py", line 72, in __exit__
    with_traceback=exc_tb,
  File "/home/mynguyen/.local/lib/python3.6/site-packages/sqlalchemy/util/compat.py", line 211, in raise_
    raise exception
  File "/home/mynguyen/.local/lib/python3.6/site-packages/sqlalchemy/pool/base.py", line 686, in __connect
    self.dbapi_connection = connection = pool._invoke_creator(self)
  File "/home/mynguyen/.local/lib/python3.6/site-packages/sqlalchemy/engine/create.py", line 574, in connect
    return dialect.connect(*cargs, **cparams)
  File "/home/mynguyen/.local/lib/python3.6/site-packages/sqlalchemy/engine/default.py", line 598, in connect
    return self.dbapi.connect(*cargs, **cparams)
  File "/home/mynguyen/.local/lib/python3.6/site-packages/psycopg2/__init__.py", line 122, in connect
    conn = _connect(dsn, connection_factory=connection_factory, **kwasync)
sqlalchemy.exc.OperationalError: (psycopg2.OperationalError) could not connect to server: Connection refused
	Is the server running on host "localhost" (127.0.0.1) and accepting
	TCP/IP connections on port 13490?

(Background on this error at: https://sqlalche.me/e/14/e3q8)
Traceback (most recent call last):
  File "/home/mynguyen/.local/lib/python3.6/site-packages/sqlalchemy/engine/base.py", line 3371, in _wrap_pool_connect
    return fn()
  File "/home/mynguyen/.local/lib/python3.6/site-packages/sqlalchemy/pool/base.py", line 327, in connect
    return _ConnectionFairy._checkout(self)
  File "/home/mynguyen/.local/lib/python3.6/site-packages/sqlalchemy/pool/base.py", line 894, in _checkout
    fairy = _ConnectionRecord.checkout(pool)
  File "/home/mynguyen/.local/lib/python3.6/site-packages/sqlalchemy/pool/base.py", line 493, in checkout
    rec = pool._do_get()
  File "/home/mynguyen/.local/lib/python3.6/site-packages/sqlalchemy/pool/impl.py", line 146, in _do_get
    self._dec_overflow()
  File "/home/mynguyen/.local/lib/python3.6/site-packages/sqlalchemy/util/langhelpers.py", line 72, in __exit__
    with_traceback=exc_tb,
  File "/home/mynguyen/.local/lib/python3.6/site-packages/sqlalchemy/util/compat.py", line 211, in raise_
    raise exception
  File "/home/mynguyen/.local/lib/python3.6/site-packages/sqlalchemy/pool/impl.py", line 143, in _do_get
    return self._create_connection()
  File "/home/mynguyen/.local/lib/python3.6/site-packages/sqlalchemy/pool/base.py", line 273, in _create_connection
    return _ConnectionRecord(self)
  File "/home/mynguyen/.local/lib/python3.6/site-packages/sqlalchemy/pool/base.py", line 388, in __init__
    self.__connect()
  File "/home/mynguyen/.local/lib/python3.6/site-packages/sqlalchemy/pool/base.py", line 691, in __connect
    pool.logger.debug("Error on connect(): %s", e)
  File "/home/mynguyen/.local/lib/python3.6/site-packages/sqlalchemy/util/langhelpers.py", line 72, in __exit__
    with_traceback=exc_tb,
  File "/home/mynguyen/.local/lib/python3.6/site-packages/sqlalchemy/util/compat.py", line 211, in raise_
    raise exception
  File "/home/mynguyen/.local/lib/python3.6/site-packages/sqlalchemy/pool/base.py", line 686, in __connect
    self.dbapi_connection = connection = pool._invoke_creator(self)
  File "/home/mynguyen/.local/lib/python3.6/site-packages/sqlalchemy/engine/create.py", line 574, in connect
    return dialect.connect(*cargs, **cparams)
  File "/home/mynguyen/.local/lib/python3.6/site-packages/sqlalchemy/engine/default.py", line 598, in connect
    return self.dbapi.connect(*cargs, **cparams)
  File "/home/mynguyen/.local/lib/python3.6/site-packages/psycopg2/__init__.py", line 122, in connect
    conn = _connect(dsn, connection_factory=connection_factory, **kwasync)
psycopg2.OperationalError: could not connect to server: Connection refused
	Is the server running on host "localhost" (127.0.0.1) and accepting
	TCP/IP connections on port 13490?


The above exception was the direct cause of the following exception:

Traceback (most recent call last):
  File "load_tweets.py", line 345, in <module>
    connection = engine.connect()
  File "/home/mynguyen/.local/lib/python3.6/site-packages/sqlalchemy/engine/base.py", line 3325, in connect
    return self._connection_cls(self, close_with_result=close_with_result)
  File "/home/mynguyen/.local/lib/python3.6/site-packages/sqlalchemy/engine/base.py", line 96, in __init__
    else engine.raw_connection()
  File "/home/mynguyen/.local/lib/python3.6/site-packages/sqlalchemy/engine/base.py", line 3404, in raw_connection
    return self._wrap_pool_connect(self.pool.connect, _connection)
  File "/home/mynguyen/.local/lib/python3.6/site-packages/sqlalchemy/engine/base.py", line 3375, in _wrap_pool_connect
    e, dialect, self
  File "/home/mynguyen/.local/lib/python3.6/site-packages/sqlalchemy/engine/base.py", line 2209, in _handle_dbapi_exception_noconnection
    sqlalchemy_exception, with_traceback=exc_info[2], from_=e
  File "/home/mynguyen/.local/lib/python3.6/site-packages/sqlalchemy/util/compat.py", line 211, in raise_
    raise exception
  File "/home/mynguyen/.local/lib/python3.6/site-packages/sqlalchemy/engine/base.py", line 3371, in _wrap_pool_connect
    return fn()
  File "/home/mynguyen/.local/lib/python3.6/site-packages/sqlalchemy/pool/base.py", line 327, in connect
    return _ConnectionFairy._checkout(self)
  File "/home/mynguyen/.local/lib/python3.6/site-packages/sqlalchemy/pool/base.py", line 894, in _checkout
    fairy = _ConnectionRecord.checkout(pool)
  File "/home/mynguyen/.local/lib/python3.6/site-packages/sqlalchemy/pool/base.py", line 493, in checkout
    rec = pool._do_get()
  File "/home/mynguyen/.local/lib/python3.6/site-packages/sqlalchemy/pool/impl.py", line 146, in _do_get
    self._dec_overflow()
  File "/home/mynguyen/.local/lib/python3.6/site-packages/sqlalchemy/util/langhelpers.py", line 72, in __exit__
    with_traceback=exc_tb,
  File "/home/mynguyen/.local/lib/python3.6/site-packages/sqlalchemy/util/compat.py", line 211, in raise_
    raise exception
  File "/home/mynguyen/.local/lib/python3.6/site-packages/sqlalchemy/pool/impl.py", line 143, in _do_get
    return self._create_connection()
  File "/home/mynguyen/.local/lib/python3.6/site-packages/sqlalchemy/pool/base.py", line 273, in _create_connection
    return _ConnectionRecord(self)
  File "/home/mynguyen/.local/lib/python3.6/site-packages/sqlalchemy/pool/base.py", line 388, in __init__
    self.__connect()
  File "/home/mynguyen/.local/lib/python3.6/site-packages/sqlalchemy/pool/base.py", line 691, in __connect
    pool.logger.debug("Error on connect(): %s", e)
  File "/home/mynguyen/.local/lib/python3.6/site-packages/sqlalchemy/util/langhelpers.py", line 72, in __exit__
    with_traceback=exc_tb,
  File "/home/mynguyen/.local/lib/python3.6/site-packages/sqlalchemy/util/compat.py", line 211, in raise_
    raise exception
  File "/home/mynguyen/.local/lib/python3.6/site-packages/sqlalchemy/pool/base.py", line 686, in __connect
    self.dbapi_connection = connection = pool._invoke_creator(self)
  File "/home/mynguyen/.local/lib/python3.6/site-packages/sqlalchemy/engine/create.py", line 574, in connect
    return dialect.connect(*cargs, **cparams)
  File "/home/mynguyen/.local/lib/python3.6/site-packages/sqlalchemy/engine/default.py", line 598, in connect
    return self.dbapi.connect(*cargs, **cparams)
  File "/home/mynguyen/.local/lib/python3.6/site-packages/psycopg2/__init__.py", line 122, in connect
    conn = _connect(dsn, connection_factory=connection_factory, **kwasync)
sqlalchemy.exc.OperationalError: (psycopg2.OperationalError) could not connect to server: Connection refused
	Is the server running on host "localhost" (127.0.0.1) and accepting
	TCP/IP connections on port 13490?

(Background on this error at: https://sqlalche.me/e/14/e3q8)
Traceback (most recent call last):
  File "/home/mynguyen/.local/lib/python3.6/site-packages/sqlalchemy/engine/base.py", line 3371, in _wrap_pool_connect
    return fn()
  File "/home/mynguyen/.local/lib/python3.6/site-packages/sqlalchemy/pool/base.py", line 327, in connect
    return _ConnectionFairy._checkout(self)
  File "/home/mynguyen/.local/lib/python3.6/site-packages/sqlalchemy/pool/base.py", line 894, in _checkout
    fairy = _ConnectionRecord.checkout(pool)
  File "/home/mynguyen/.local/lib/python3.6/site-packages/sqlalchemy/pool/base.py", line 493, in checkout
    rec = pool._do_get()
  File "/home/mynguyen/.local/lib/python3.6/site-packages/sqlalchemy/pool/impl.py", line 146, in _do_get
    self._dec_overflow()
  File "/home/mynguyen/.local/lib/python3.6/site-packages/sqlalchemy/util/langhelpers.py", line 72, in __exit__
    with_traceback=exc_tb,
  File "/home/mynguyen/.local/lib/python3.6/site-packages/sqlalchemy/util/compat.py", line 211, in raise_
    raise exception
  File "/home/mynguyen/.local/lib/python3.6/site-packages/sqlalchemy/pool/impl.py", line 143, in _do_get
    return self._create_connection()
  File "/home/mynguyen/.local/lib/python3.6/site-packages/sqlalchemy/pool/base.py", line 273, in _create_connection
    return _ConnectionRecord(self)
  File "/home/mynguyen/.local/lib/python3.6/site-packages/sqlalchemy/pool/base.py", line 388, in __init__
    self.__connect()
  File "/home/mynguyen/.local/lib/python3.6/site-packages/sqlalchemy/pool/base.py", line 691, in __connect
    pool.logger.debug("Error on connect(): %s", e)
  File "/home/mynguyen/.local/lib/python3.6/site-packages/sqlalchemy/util/langhelpers.py", line 72, in __exit__
    with_traceback=exc_tb,
  File "/home/mynguyen/.local/lib/python3.6/site-packages/sqlalchemy/util/compat.py", line 211, in raise_
    raise exception
  File "/home/mynguyen/.local/lib/python3.6/site-packages/sqlalchemy/pool/base.py", line 686, in __connect
    self.dbapi_connection = connection = pool._invoke_creator(self)
  File "/home/mynguyen/.local/lib/python3.6/site-packages/sqlalchemy/engine/create.py", line 574, in connect
    return dialect.connect(*cargs, **cparams)
  File "/home/mynguyen/.local/lib/python3.6/site-packages/sqlalchemy/engine/default.py", line 598, in connect
    return self.dbapi.connect(*cargs, **cparams)
  File "/home/mynguyen/.local/lib/python3.6/site-packages/psycopg2/__init__.py", line 122, in connect
    conn = _connect(dsn, connection_factory=connection_factory, **kwasync)
psycopg2.OperationalError: could not connect to server: Connection refused
	Is the server running on host "localhost" (127.0.0.1) and accepting
	TCP/IP connections on port 13490?


The above exception was the direct cause of the following exception:

Traceback (most recent call last):
  File "load_tweets.py", line 345, in <module>
    connection = engine.connect()
  File "/home/mynguyen/.local/lib/python3.6/site-packages/sqlalchemy/engine/base.py", line 3325, in connect
    return self._connection_cls(self, close_with_result=close_with_result)
  File "/home/mynguyen/.local/lib/python3.6/site-packages/sqlalchemy/engine/base.py", line 96, in __init__
    else engine.raw_connection()
  File "/home/mynguyen/.local/lib/python3.6/site-packages/sqlalchemy/engine/base.py", line 3404, in raw_connection
    return self._wrap_pool_connect(self.pool.connect, _connection)
  File "/home/mynguyen/.local/lib/python3.6/site-packages/sqlalchemy/engine/base.py", line 3375, in _wrap_pool_connect
    e, dialect, self
  File "/home/mynguyen/.local/lib/python3.6/site-packages/sqlalchemy/engine/base.py", line 2209, in _handle_dbapi_exception_noconnection
    sqlalchemy_exception, with_traceback=exc_info[2], from_=e
  File "/home/mynguyen/.local/lib/python3.6/site-packages/sqlalchemy/util/compat.py", line 211, in raise_
    raise exception
  File "/home/mynguyen/.local/lib/python3.6/site-packages/sqlalchemy/engine/base.py", line 3371, in _wrap_pool_connect
    return fn()
  File "/home/mynguyen/.local/lib/python3.6/site-packages/sqlalchemy/pool/base.py", line 327, in connect
    return _ConnectionFairy._checkout(self)
  File "/home/mynguyen/.local/lib/python3.6/site-packages/sqlalchemy/pool/base.py", line 894, in _checkout
    fairy = _ConnectionRecord.checkout(pool)
  File "/home/mynguyen/.local/lib/python3.6/site-packages/sqlalchemy/pool/base.py", line 493, in checkout
    rec = pool._do_get()
  File "/home/mynguyen/.local/lib/python3.6/site-packages/sqlalchemy/pool/impl.py", line 146, in _do_get
    self._dec_overflow()
  File "/home/mynguyen/.local/lib/python3.6/site-packages/sqlalchemy/util/langhelpers.py", line 72, in __exit__
    with_traceback=exc_tb,
  File "/home/mynguyen/.local/lib/python3.6/site-packages/sqlalchemy/util/compat.py", line 211, in raise_
    raise exception
  File "/home/mynguyen/.local/lib/python3.6/site-packages/sqlalchemy/pool/impl.py", line 143, in _do_get
    return self._create_connection()
  File "/home/mynguyen/.local/lib/python3.6/site-packages/sqlalchemy/pool/base.py", line 273, in _create_connection
    return _ConnectionRecord(self)
  File "/home/mynguyen/.local/lib/python3.6/site-packages/sqlalchemy/pool/base.py", line 388, in __init__
    self.__connect()
  File "/home/mynguyen/.local/lib/python3.6/site-packages/sqlalchemy/pool/base.py", line 691, in __connect
    pool.logger.debug("Error on connect(): %s", e)
  File "/home/mynguyen/.local/lib/python3.6/site-packages/sqlalchemy/util/langhelpers.py", line 72, in __exit__
    with_traceback=exc_tb,
  File "/home/mynguyen/.local/lib/python3.6/site-packages/sqlalchemy/util/compat.py", line 211, in raise_
    raise exception
  File "/home/mynguyen/.local/lib/python3.6/site-packages/sqlalchemy/pool/base.py", line 686, in __connect
    self.dbapi_connection = connection = pool._invoke_creator(self)
  File "/home/mynguyen/.local/lib/python3.6/site-packages/sqlalchemy/engine/create.py", line 574, in connect
    return dialect.connect(*cargs, **cparams)
  File "/home/mynguyen/.local/lib/python3.6/site-packages/sqlalchemy/engine/default.py", line 598, in connect
    return self.dbapi.connect(*cargs, **cparams)
  File "/home/mynguyen/.local/lib/python3.6/site-packages/psycopg2/__init__.py", line 122, in connect
    conn = _connect(dsn, connection_factory=connection_factory, **kwasync)
sqlalchemy.exc.OperationalError: (psycopg2.OperationalError) could not connect to server: Connection refused
	Is the server running on host "localhost" (127.0.0.1) and accepting
	TCP/IP connections on port 13490?

(Background on this error at: https://sqlalche.me/e/14/e3q8)
Traceback (most recent call last):
  File "/home/mynguyen/.local/lib/python3.6/site-packages/sqlalchemy/engine/base.py", line 3371, in _wrap_pool_connect
    return fn()
  File "/home/mynguyen/.local/lib/python3.6/site-packages/sqlalchemy/pool/base.py", line 327, in connect
    return _ConnectionFairy._checkout(self)
  File "/home/mynguyen/.local/lib/python3.6/site-packages/sqlalchemy/pool/base.py", line 894, in _checkout
    fairy = _ConnectionRecord.checkout(pool)
  File "/home/mynguyen/.local/lib/python3.6/site-packages/sqlalchemy/pool/base.py", line 493, in checkout
    rec = pool._do_get()
  File "/home/mynguyen/.local/lib/python3.6/site-packages/sqlalchemy/pool/impl.py", line 146, in _do_get
    self._dec_overflow()
  File "/home/mynguyen/.local/lib/python3.6/site-packages/sqlalchemy/util/langhelpers.py", line 72, in __exit__
    with_traceback=exc_tb,
  File "/home/mynguyen/.local/lib/python3.6/site-packages/sqlalchemy/util/compat.py", line 211, in raise_
    raise exception
  File "/home/mynguyen/.local/lib/python3.6/site-packages/sqlalchemy/pool/impl.py", line 143, in _do_get
    return self._create_connection()
  File "/home/mynguyen/.local/lib/python3.6/site-packages/sqlalchemy/pool/base.py", line 273, in _create_connection
    return _ConnectionRecord(self)
  File "/home/mynguyen/.local/lib/python3.6/site-packages/sqlalchemy/pool/base.py", line 388, in __init__
    self.__connect()
  File "/home/mynguyen/.local/lib/python3.6/site-packages/sqlalchemy/pool/base.py", line 691, in __connect
    pool.logger.debug("Error on connect(): %s", e)
  File "/home/mynguyen/.local/lib/python3.6/site-packages/sqlalchemy/util/langhelpers.py", line 72, in __exit__
    with_traceback=exc_tb,
  File "/home/mynguyen/.local/lib/python3.6/site-packages/sqlalchemy/util/compat.py", line 211, in raise_
    raise exception
  File "/home/mynguyen/.local/lib/python3.6/site-packages/sqlalchemy/pool/base.py", line 686, in __connect
    self.dbapi_connection = connection = pool._invoke_creator(self)
  File "/home/mynguyen/.local/lib/python3.6/site-packages/sqlalchemy/engine/create.py", line 574, in connect
    return dialect.connect(*cargs, **cparams)
  File "/home/mynguyen/.local/lib/python3.6/site-packages/sqlalchemy/engine/default.py", line 598, in connect
    return self.dbapi.connect(*cargs, **cparams)
  File "/home/mynguyen/.local/lib/python3.6/site-packages/psycopg2/__init__.py", line 122, in connect
    conn = _connect(dsn, connection_factory=connection_factory, **kwasync)
psycopg2.OperationalError: could not connect to server: Connection refused
	Is the server running on host "localhost" (127.0.0.1) and accepting
	TCP/IP connections on port 13490?


The above exception was the direct cause of the following exception:

Traceback (most recent call last):
  File "load_tweets.py", line 345, in <module>
    connection = engine.connect()
  File "/home/mynguyen/.local/lib/python3.6/site-packages/sqlalchemy/engine/base.py", line 3325, in connect
    return self._connection_cls(self, close_with_result=close_with_result)
  File "/home/mynguyen/.local/lib/python3.6/site-packages/sqlalchemy/engine/base.py", line 96, in __init__
    else engine.raw_connection()
  File "/home/mynguyen/.local/lib/python3.6/site-packages/sqlalchemy/engine/base.py", line 3404, in raw_connection
    return self._wrap_pool_connect(self.pool.connect, _connection)
  File "/home/mynguyen/.local/lib/python3.6/site-packages/sqlalchemy/engine/base.py", line 3375, in _wrap_pool_connect
    e, dialect, self
  File "/home/mynguyen/.local/lib/python3.6/site-packages/sqlalchemy/engine/base.py", line 2209, in _handle_dbapi_exception_noconnection
    sqlalchemy_exception, with_traceback=exc_info[2], from_=e
  File "/home/mynguyen/.local/lib/python3.6/site-packages/sqlalchemy/util/compat.py", line 211, in raise_
    raise exception
  File "/home/mynguyen/.local/lib/python3.6/site-packages/sqlalchemy/engine/base.py", line 3371, in _wrap_pool_connect
    return fn()
  File "/home/mynguyen/.local/lib/python3.6/site-packages/sqlalchemy/pool/base.py", line 327, in connect
    return _ConnectionFairy._checkout(self)
  File "/home/mynguyen/.local/lib/python3.6/site-packages/sqlalchemy/pool/base.py", line 894, in _checkout
    fairy = _ConnectionRecord.checkout(pool)
  File "/home/mynguyen/.local/lib/python3.6/site-packages/sqlalchemy/pool/base.py", line 493, in checkout
    rec = pool._do_get()
  File "/home/mynguyen/.local/lib/python3.6/site-packages/sqlalchemy/pool/impl.py", line 146, in _do_get
    self._dec_overflow()
  File "/home/mynguyen/.local/lib/python3.6/site-packages/sqlalchemy/util/langhelpers.py", line 72, in __exit__
    with_traceback=exc_tb,
  File "/home/mynguyen/.local/lib/python3.6/site-packages/sqlalchemy/util/compat.py", line 211, in raise_
    raise exception
  File "/home/mynguyen/.local/lib/python3.6/site-packages/sqlalchemy/pool/impl.py", line 143, in _do_get
    return self._create_connection()
  File "/home/mynguyen/.local/lib/python3.6/site-packages/sqlalchemy/pool/base.py", line 273, in _create_connection
    return _ConnectionRecord(self)
  File "/home/mynguyen/.local/lib/python3.6/site-packages/sqlalchemy/pool/base.py", line 388, in __init__
    self.__connect()
  File "/home/mynguyen/.local/lib/python3.6/site-packages/sqlalchemy/pool/base.py", line 691, in __connect
    pool.logger.debug("Error on connect(): %s", e)
  File "/home/mynguyen/.local/lib/python3.6/site-packages/sqlalchemy/util/langhelpers.py", line 72, in __exit__
    with_traceback=exc_tb,
  File "/home/mynguyen/.local/lib/python3.6/site-packages/sqlalchemy/util/compat.py", line 211, in raise_
    raise exception
  File "/home/mynguyen/.local/lib/python3.6/site-packages/sqlalchemy/pool/base.py", line 686, in __connect
    self.dbapi_connection = connection = pool._invoke_creator(self)
  File "/home/mynguyen/.local/lib/python3.6/site-packages/sqlalchemy/engine/create.py", line 574, in connect
    return dialect.connect(*cargs, **cparams)
  File "/home/mynguyen/.local/lib/python3.6/site-packages/sqlalchemy/engine/default.py", line 598, in connect
    return self.dbapi.connect(*cargs, **cparams)
  File "/home/mynguyen/.local/lib/python3.6/site-packages/psycopg2/__init__.py", line 122, in connect
    conn = _connect(dsn, connection_factory=connection_factory, **kwasync)
sqlalchemy.exc.OperationalError: (psycopg2.OperationalError) could not connect to server: Connection refused
	Is the server running on host "localhost" (127.0.0.1) and accepting
	TCP/IP connections on port 13490?

(Background on this error at: https://sqlalche.me/e/14/e3q8)
Traceback (most recent call last):
  File "/home/mynguyen/.local/lib/python3.6/site-packages/sqlalchemy/engine/base.py", line 3371, in _wrap_pool_connect
    return fn()
  File "/home/mynguyen/.local/lib/python3.6/site-packages/sqlalchemy/pool/base.py", line 327, in connect
    return _ConnectionFairy._checkout(self)
  File "/home/mynguyen/.local/lib/python3.6/site-packages/sqlalchemy/pool/base.py", line 894, in _checkout
    fairy = _ConnectionRecord.checkout(pool)
  File "/home/mynguyen/.local/lib/python3.6/site-packages/sqlalchemy/pool/base.py", line 493, in checkout
    rec = pool._do_get()
  File "/home/mynguyen/.local/lib/python3.6/site-packages/sqlalchemy/pool/impl.py", line 146, in _do_get
    self._dec_overflow()
  File "/home/mynguyen/.local/lib/python3.6/site-packages/sqlalchemy/util/langhelpers.py", line 72, in __exit__
    with_traceback=exc_tb,
  File "/home/mynguyen/.local/lib/python3.6/site-packages/sqlalchemy/util/compat.py", line 211, in raise_
    raise exception
  File "/home/mynguyen/.local/lib/python3.6/site-packages/sqlalchemy/pool/impl.py", line 143, in _do_get
    return self._create_connection()
  File "/home/mynguyen/.local/lib/python3.6/site-packages/sqlalchemy/pool/base.py", line 273, in _create_connection
    return _ConnectionRecord(self)
  File "/home/mynguyen/.local/lib/python3.6/site-packages/sqlalchemy/pool/base.py", line 388, in __init__
    self.__connect()
  File "/home/mynguyen/.local/lib/python3.6/site-packages/sqlalchemy/pool/base.py", line 691, in __connect
    pool.logger.debug("Error on connect(): %s", e)
  File "/home/mynguyen/.local/lib/python3.6/site-packages/sqlalchemy/util/langhelpers.py", line 72, in __exit__
    with_traceback=exc_tb,
  File "/home/mynguyen/.local/lib/python3.6/site-packages/sqlalchemy/util/compat.py", line 211, in raise_
    raise exception
  File "/home/mynguyen/.local/lib/python3.6/site-packages/sqlalchemy/pool/base.py", line 686, in __connect
    self.dbapi_connection = connection = pool._invoke_creator(self)
  File "/home/mynguyen/.local/lib/python3.6/site-packages/sqlalchemy/engine/create.py", line 574, in connect
    return dialect.connect(*cargs, **cparams)
  File "/home/mynguyen/.local/lib/python3.6/site-packages/sqlalchemy/engine/default.py", line 598, in connect
    return self.dbapi.connect(*cargs, **cparams)
  File "/home/mynguyen/.local/lib/python3.6/site-packages/psycopg2/__init__.py", line 122, in connect
    conn = _connect(dsn, connection_factory=connection_factory, **kwasync)
psycopg2.OperationalError: could not connect to server: Connection refused
	Is the server running on host "localhost" (127.0.0.1) and accepting
	TCP/IP connections on port 13490?


The above exception was the direct cause of the following exception:

Traceback (most recent call last):
  File "load_tweets.py", line 345, in <module>
    connection = engine.connect()
  File "/home/mynguyen/.local/lib/python3.6/site-packages/sqlalchemy/engine/base.py", line 3325, in connect
    return self._connection_cls(self, close_with_result=close_with_result)
  File "/home/mynguyen/.local/lib/python3.6/site-packages/sqlalchemy/engine/base.py", line 96, in __init__
    else engine.raw_connection()
  File "/home/mynguyen/.local/lib/python3.6/site-packages/sqlalchemy/engine/base.py", line 3404, in raw_connection
    return self._wrap_pool_connect(self.pool.connect, _connection)
  File "/home/mynguyen/.local/lib/python3.6/site-packages/sqlalchemy/engine/base.py", line 3375, in _wrap_pool_connect
    e, dialect, self
  File "/home/mynguyen/.local/lib/python3.6/site-packages/sqlalchemy/engine/base.py", line 2209, in _handle_dbapi_exception_noconnection
    sqlalchemy_exception, with_traceback=exc_info[2], from_=e
  File "/home/mynguyen/.local/lib/python3.6/site-packages/sqlalchemy/util/compat.py", line 211, in raise_
    raise exception
  File "/home/mynguyen/.local/lib/python3.6/site-packages/sqlalchemy/engine/base.py", line 3371, in _wrap_pool_connect
    return fn()
  File "/home/mynguyen/.local/lib/python3.6/site-packages/sqlalchemy/pool/base.py", line 327, in connect
    return _ConnectionFairy._checkout(self)
  File "/home/mynguyen/.local/lib/python3.6/site-packages/sqlalchemy/pool/base.py", line 894, in _checkout
    fairy = _ConnectionRecord.checkout(pool)
  File "/home/mynguyen/.local/lib/python3.6/site-packages/sqlalchemy/pool/base.py", line 493, in checkout
    rec = pool._do_get()
  File "/home/mynguyen/.local/lib/python3.6/site-packages/sqlalchemy/pool/impl.py", line 146, in _do_get
    self._dec_overflow()
  File "/home/mynguyen/.local/lib/python3.6/site-packages/sqlalchemy/util/langhelpers.py", line 72, in __exit__
    with_traceback=exc_tb,
  File "/home/mynguyen/.local/lib/python3.6/site-packages/sqlalchemy/util/compat.py", line 211, in raise_
    raise exception
  File "/home/mynguyen/.local/lib/python3.6/site-packages/sqlalchemy/pool/impl.py", line 143, in _do_get
    return self._create_connection()
  File "/home/mynguyen/.local/lib/python3.6/site-packages/sqlalchemy/pool/base.py", line 273, in _create_connection
    return _ConnectionRecord(self)
  File "/home/mynguyen/.local/lib/python3.6/site-packages/sqlalchemy/pool/base.py", line 388, in __init__
    self.__connect()
  File "/home/mynguyen/.local/lib/python3.6/site-packages/sqlalchemy/pool/base.py", line 691, in __connect
    pool.logger.debug("Error on connect(): %s", e)
  File "/home/mynguyen/.local/lib/python3.6/site-packages/sqlalchemy/util/langhelpers.py", line 72, in __exit__
    with_traceback=exc_tb,
  File "/home/mynguyen/.local/lib/python3.6/site-packages/sqlalchemy/util/compat.py", line 211, in raise_
    raise exception
  File "/home/mynguyen/.local/lib/python3.6/site-packages/sqlalchemy/pool/base.py", line 686, in __connect
    self.dbapi_connection = connection = pool._invoke_creator(self)
  File "/home/mynguyen/.local/lib/python3.6/site-packages/sqlalchemy/engine/create.py", line 574, in connect
    return dialect.connect(*cargs, **cparams)
  File "/home/mynguyen/.local/lib/python3.6/site-packages/sqlalchemy/engine/default.py", line 598, in connect
    return self.dbapi.connect(*cargs, **cparams)
  File "/home/mynguyen/.local/lib/python3.6/site-packages/psycopg2/__init__.py", line 122, in connect
    conn = _connect(dsn, connection_factory=connection_factory, **kwasync)
sqlalchemy.exc.OperationalError: (psycopg2.OperationalError) could not connect to server: Connection refused
	Is the server running on host "localhost" (127.0.0.1) and accepting
	TCP/IP connections on port 13490?

(Background on this error at: https://sqlalche.me/e/14/e3q8)
Traceback (most recent call last):
  File "/home/mynguyen/.local/lib/python3.6/site-packages/sqlalchemy/engine/base.py", line 3371, in _wrap_pool_connect
    return fn()
  File "/home/mynguyen/.local/lib/python3.6/site-packages/sqlalchemy/pool/base.py", line 327, in connect
    return _ConnectionFairy._checkout(self)
  File "/home/mynguyen/.local/lib/python3.6/site-packages/sqlalchemy/pool/base.py", line 894, in _checkout
    fairy = _ConnectionRecord.checkout(pool)
  File "/home/mynguyen/.local/lib/python3.6/site-packages/sqlalchemy/pool/base.py", line 493, in checkout
    rec = pool._do_get()
  File "/home/mynguyen/.local/lib/python3.6/site-packages/sqlalchemy/pool/impl.py", line 146, in _do_get
    self._dec_overflow()
  File "/home/mynguyen/.local/lib/python3.6/site-packages/sqlalchemy/util/langhelpers.py", line 72, in __exit__
    with_traceback=exc_tb,
  File "/home/mynguyen/.local/lib/python3.6/site-packages/sqlalchemy/util/compat.py", line 211, in raise_
    raise exception
  File "/home/mynguyen/.local/lib/python3.6/site-packages/sqlalchemy/pool/impl.py", line 143, in _do_get
    return self._create_connection()
  File "/home/mynguyen/.local/lib/python3.6/site-packages/sqlalchemy/pool/base.py", line 273, in _create_connection
    return _ConnectionRecord(self)
  File "/home/mynguyen/.local/lib/python3.6/site-packages/sqlalchemy/pool/base.py", line 388, in __init__
    self.__connect()
  File "/home/mynguyen/.local/lib/python3.6/site-packages/sqlalchemy/pool/base.py", line 691, in __connect
    pool.logger.debug("Error on connect(): %s", e)
  File "/home/mynguyen/.local/lib/python3.6/site-packages/sqlalchemy/util/langhelpers.py", line 72, in __exit__
    with_traceback=exc_tb,
  File "/home/mynguyen/.local/lib/python3.6/site-packages/sqlalchemy/util/compat.py", line 211, in raise_
    raise exception
  File "/home/mynguyen/.local/lib/python3.6/site-packages/sqlalchemy/pool/base.py", line 686, in __connect
    self.dbapi_connection = connection = pool._invoke_creator(self)
  File "/home/mynguyen/.local/lib/python3.6/site-packages/sqlalchemy/engine/create.py", line 574, in connect
    return dialect.connect(*cargs, **cparams)
  File "/home/mynguyen/.local/lib/python3.6/site-packages/sqlalchemy/engine/default.py", line 598, in connect
    return self.dbapi.connect(*cargs, **cparams)
  File "/home/mynguyen/.local/lib/python3.6/site-packages/psycopg2/__init__.py", line 122, in connect
    conn = _connect(dsn, connection_factory=connection_factory, **kwasync)
psycopg2.OperationalError: could not connect to server: Connection refused
	Is the server running on host "localhost" (127.0.0.1) and accepting
	TCP/IP connections on port 13490?


The above exception was the direct cause of the following exception:

Traceback (most recent call last):
  File "load_tweets.py", line 345, in <module>
    connection = engine.connect()
  File "/home/mynguyen/.local/lib/python3.6/site-packages/sqlalchemy/engine/base.py", line 3325, in connect
    return self._connection_cls(self, close_with_result=close_with_result)
  File "/home/mynguyen/.local/lib/python3.6/site-packages/sqlalchemy/engine/base.py", line 96, in __init__
    else engine.raw_connection()
  File "/home/mynguyen/.local/lib/python3.6/site-packages/sqlalchemy/engine/base.py", line 3404, in raw_connection
    return self._wrap_pool_connect(self.pool.connect, _connection)
  File "/home/mynguyen/.local/lib/python3.6/site-packages/sqlalchemy/engine/base.py", line 3375, in _wrap_pool_connect
    e, dialect, self
  File "/home/mynguyen/.local/lib/python3.6/site-packages/sqlalchemy/engine/base.py", line 2209, in _handle_dbapi_exception_noconnection
    sqlalchemy_exception, with_traceback=exc_info[2], from_=e
  File "/home/mynguyen/.local/lib/python3.6/site-packages/sqlalchemy/util/compat.py", line 211, in raise_
    raise exception
  File "/home/mynguyen/.local/lib/python3.6/site-packages/sqlalchemy/engine/base.py", line 3371, in _wrap_pool_connect
    return fn()
  File "/home/mynguyen/.local/lib/python3.6/site-packages/sqlalchemy/pool/base.py", line 327, in connect
    return _ConnectionFairy._checkout(self)
  File "/home/mynguyen/.local/lib/python3.6/site-packages/sqlalchemy/pool/base.py", line 894, in _checkout
    fairy = _ConnectionRecord.checkout(pool)
  File "/home/mynguyen/.local/lib/python3.6/site-packages/sqlalchemy/pool/base.py", line 493, in checkout
    rec = pool._do_get()
  File "/home/mynguyen/.local/lib/python3.6/site-packages/sqlalchemy/pool/impl.py", line 146, in _do_get
    self._dec_overflow()
  File "/home/mynguyen/.local/lib/python3.6/site-packages/sqlalchemy/util/langhelpers.py", line 72, in __exit__
    with_traceback=exc_tb,
  File "/home/mynguyen/.local/lib/python3.6/site-packages/sqlalchemy/util/compat.py", line 211, in raise_
    raise exception
  File "/home/mynguyen/.local/lib/python3.6/site-packages/sqlalchemy/pool/impl.py", line 143, in _do_get
    return self._create_connection()
  File "/home/mynguyen/.local/lib/python3.6/site-packages/sqlalchemy/pool/base.py", line 273, in _create_connection
    return _ConnectionRecord(self)
  File "/home/mynguyen/.local/lib/python3.6/site-packages/sqlalchemy/pool/base.py", line 388, in __init__
    self.__connect()
  File "/home/mynguyen/.local/lib/python3.6/site-packages/sqlalchemy/pool/base.py", line 691, in __connect
    pool.logger.debug("Error on connect(): %s", e)
  File "/home/mynguyen/.local/lib/python3.6/site-packages/sqlalchemy/util/langhelpers.py", line 72, in __exit__
    with_traceback=exc_tb,
  File "/home/mynguyen/.local/lib/python3.6/site-packages/sqlalchemy/util/compat.py", line 211, in raise_
    raise exception
  File "/home/mynguyen/.local/lib/python3.6/site-packages/sqlalchemy/pool/base.py", line 686, in __connect
    self.dbapi_connection = connection = pool._invoke_creator(self)
  File "/home/mynguyen/.local/lib/python3.6/site-packages/sqlalchemy/engine/create.py", line 574, in connect
    return dialect.connect(*cargs, **cparams)
  File "/home/mynguyen/.local/lib/python3.6/site-packages/sqlalchemy/engine/default.py", line 598, in connect
    return self.dbapi.connect(*cargs, **cparams)
  File "/home/mynguyen/.local/lib/python3.6/site-packages/psycopg2/__init__.py", line 122, in connect
    conn = _connect(dsn, connection_factory=connection_factory, **kwasync)
sqlalchemy.exc.OperationalError: (psycopg2.OperationalError) could not connect to server: Connection refused
	Is the server running on host "localhost" (127.0.0.1) and accepting
	TCP/IP connections on port 13490?

(Background on this error at: https://sqlalche.me/e/14/e3q8)
Traceback (most recent call last):
  File "/home/mynguyen/.local/lib/python3.6/site-packages/sqlalchemy/engine/base.py", line 3371, in _wrap_pool_connect
    return fn()
  File "/home/mynguyen/.local/lib/python3.6/site-packages/sqlalchemy/pool/base.py", line 327, in connect
    return _ConnectionFairy._checkout(self)
  File "/home/mynguyen/.local/lib/python3.6/site-packages/sqlalchemy/pool/base.py", line 894, in _checkout
    fairy = _ConnectionRecord.checkout(pool)
  File "/home/mynguyen/.local/lib/python3.6/site-packages/sqlalchemy/pool/base.py", line 493, in checkout
    rec = pool._do_get()
  File "/home/mynguyen/.local/lib/python3.6/site-packages/sqlalchemy/pool/impl.py", line 146, in _do_get
    self._dec_overflow()
  File "/home/mynguyen/.local/lib/python3.6/site-packages/sqlalchemy/util/langhelpers.py", line 72, in __exit__
    with_traceback=exc_tb,
  File "/home/mynguyen/.local/lib/python3.6/site-packages/sqlalchemy/util/compat.py", line 211, in raise_
    raise exception
  File "/home/mynguyen/.local/lib/python3.6/site-packages/sqlalchemy/pool/impl.py", line 143, in _do_get
    return self._create_connection()
  File "/home/mynguyen/.local/lib/python3.6/site-packages/sqlalchemy/pool/base.py", line 273, in _create_connection
    return _ConnectionRecord(self)
  File "/home/mynguyen/.local/lib/python3.6/site-packages/sqlalchemy/pool/base.py", line 388, in __init__
    self.__connect()
  File "/home/mynguyen/.local/lib/python3.6/site-packages/sqlalchemy/pool/base.py", line 691, in __connect
    pool.logger.debug("Error on connect(): %s", e)
  File "/home/mynguyen/.local/lib/python3.6/site-packages/sqlalchemy/util/langhelpers.py", line 72, in __exit__
    with_traceback=exc_tb,
  File "/home/mynguyen/.local/lib/python3.6/site-packages/sqlalchemy/util/compat.py", line 211, in raise_
    raise exception
  File "/home/mynguyen/.local/lib/python3.6/site-packages/sqlalchemy/pool/base.py", line 686, in __connect
    self.dbapi_connection = connection = pool._invoke_creator(self)
  File "/home/mynguyen/.local/lib/python3.6/site-packages/sqlalchemy/engine/create.py", line 574, in connect
    return dialect.connect(*cargs, **cparams)
  File "/home/mynguyen/.local/lib/python3.6/site-packages/sqlalchemy/engine/default.py", line 598, in connect
    return self.dbapi.connect(*cargs, **cparams)
  File "/home/mynguyen/.local/lib/python3.6/site-packages/psycopg2/__init__.py", line 122, in connect
    conn = _connect(dsn, connection_factory=connection_factory, **kwasync)
psycopg2.OperationalError: could not connect to server: Connection refused
	Is the server running on host "localhost" (127.0.0.1) and accepting
	TCP/IP connections on port 13490?


The above exception was the direct cause of the following exception:

Traceback (most recent call last):
  File "load_tweets.py", line 345, in <module>
    connection = engine.connect()
  File "/home/mynguyen/.local/lib/python3.6/site-packages/sqlalchemy/engine/base.py", line 3325, in connect
    return self._connection_cls(self, close_with_result=close_with_result)
  File "/home/mynguyen/.local/lib/python3.6/site-packages/sqlalchemy/engine/base.py", line 96, in __init__
    else engine.raw_connection()
  File "/home/mynguyen/.local/lib/python3.6/site-packages/sqlalchemy/engine/base.py", line 3404, in raw_connection
    return self._wrap_pool_connect(self.pool.connect, _connection)
  File "/home/mynguyen/.local/lib/python3.6/site-packages/sqlalchemy/engine/base.py", line 3375, in _wrap_pool_connect
    e, dialect, self
  File "/home/mynguyen/.local/lib/python3.6/site-packages/sqlalchemy/engine/base.py", line 2209, in _handle_dbapi_exception_noconnection
    sqlalchemy_exception, with_traceback=exc_info[2], from_=e
  File "/home/mynguyen/.local/lib/python3.6/site-packages/sqlalchemy/util/compat.py", line 211, in raise_
    raise exception
  File "/home/mynguyen/.local/lib/python3.6/site-packages/sqlalchemy/engine/base.py", line 3371, in _wrap_pool_connect
    return fn()
  File "/home/mynguyen/.local/lib/python3.6/site-packages/sqlalchemy/pool/base.py", line 327, in connect
    return _ConnectionFairy._checkout(self)
  File "/home/mynguyen/.local/lib/python3.6/site-packages/sqlalchemy/pool/base.py", line 894, in _checkout
    fairy = _ConnectionRecord.checkout(pool)
  File "/home/mynguyen/.local/lib/python3.6/site-packages/sqlalchemy/pool/base.py", line 493, in checkout
    rec = pool._do_get()
  File "/home/mynguyen/.local/lib/python3.6/site-packages/sqlalchemy/pool/impl.py", line 146, in _do_get
    self._dec_overflow()
  File "/home/mynguyen/.local/lib/python3.6/site-packages/sqlalchemy/util/langhelpers.py", line 72, in __exit__
    with_traceback=exc_tb,
  File "/home/mynguyen/.local/lib/python3.6/site-packages/sqlalchemy/util/compat.py", line 211, in raise_
    raise exception
  File "/home/mynguyen/.local/lib/python3.6/site-packages/sqlalchemy/pool/impl.py", line 143, in _do_get
    return self._create_connection()
  File "/home/mynguyen/.local/lib/python3.6/site-packages/sqlalchemy/pool/base.py", line 273, in _create_connection
    return _ConnectionRecord(self)
  File "/home/mynguyen/.local/lib/python3.6/site-packages/sqlalchemy/pool/base.py", line 388, in __init__
    self.__connect()
  File "/home/mynguyen/.local/lib/python3.6/site-packages/sqlalchemy/pool/base.py", line 691, in __connect
    pool.logger.debug("Error on connect(): %s", e)
  File "/home/mynguyen/.local/lib/python3.6/site-packages/sqlalchemy/util/langhelpers.py", line 72, in __exit__
    with_traceback=exc_tb,
  File "/home/mynguyen/.local/lib/python3.6/site-packages/sqlalchemy/util/compat.py", line 211, in raise_
    raise exception
  File "/home/mynguyen/.local/lib/python3.6/site-packages/sqlalchemy/pool/base.py", line 686, in __connect
    self.dbapi_connection = connection = pool._invoke_creator(self)
  File "/home/mynguyen/.local/lib/python3.6/site-packages/sqlalchemy/engine/create.py", line 574, in connect
    return dialect.connect(*cargs, **cparams)
  File "/home/mynguyen/.local/lib/python3.6/site-packages/sqlalchemy/engine/default.py", line 598, in connect
    return self.dbapi.connect(*cargs, **cparams)
  File "/home/mynguyen/.local/lib/python3.6/site-packages/psycopg2/__init__.py", line 122, in connect
    conn = _connect(dsn, connection_factory=connection_factory, **kwasync)
sqlalchemy.exc.OperationalError: (psycopg2.OperationalError) could not connect to server: Connection refused
	Is the server running on host "localhost" (127.0.0.1) and accepting
	TCP/IP connections on port 13490?

(Background on this error at: https://sqlalche.me/e/14/e3q8)
Traceback (most recent call last):
  File "/home/mynguyen/.local/lib/python3.6/site-packages/sqlalchemy/engine/base.py", line 3371, in _wrap_pool_connect
    return fn()
  File "/home/mynguyen/.local/lib/python3.6/site-packages/sqlalchemy/pool/base.py", line 327, in connect
    return _ConnectionFairy._checkout(self)
  File "/home/mynguyen/.local/lib/python3.6/site-packages/sqlalchemy/pool/base.py", line 894, in _checkout
    fairy = _ConnectionRecord.checkout(pool)
  File "/home/mynguyen/.local/lib/python3.6/site-packages/sqlalchemy/pool/base.py", line 493, in checkout
    rec = pool._do_get()
  File "/home/mynguyen/.local/lib/python3.6/site-packages/sqlalchemy/pool/impl.py", line 146, in _do_get
    self._dec_overflow()
  File "/home/mynguyen/.local/lib/python3.6/site-packages/sqlalchemy/util/langhelpers.py", line 72, in __exit__
    with_traceback=exc_tb,
  File "/home/mynguyen/.local/lib/python3.6/site-packages/sqlalchemy/util/compat.py", line 211, in raise_
    raise exception
  File "/home/mynguyen/.local/lib/python3.6/site-packages/sqlalchemy/pool/impl.py", line 143, in _do_get
    return self._create_connection()
  File "/home/mynguyen/.local/lib/python3.6/site-packages/sqlalchemy/pool/base.py", line 273, in _create_connection
    return _ConnectionRecord(self)
  File "/home/mynguyen/.local/lib/python3.6/site-packages/sqlalchemy/pool/base.py", line 388, in __init__
    self.__connect()
  File "/home/mynguyen/.local/lib/python3.6/site-packages/sqlalchemy/pool/base.py", line 691, in __connect
    pool.logger.debug("Error on connect(): %s", e)
  File "/home/mynguyen/.local/lib/python3.6/site-packages/sqlalchemy/util/langhelpers.py", line 72, in __exit__
    with_traceback=exc_tb,
  File "/home/mynguyen/.local/lib/python3.6/site-packages/sqlalchemy/util/compat.py", line 211, in raise_
    raise exception
  File "/home/mynguyen/.local/lib/python3.6/site-packages/sqlalchemy/pool/base.py", line 686, in __connect
    self.dbapi_connection = connection = pool._invoke_creator(self)
  File "/home/mynguyen/.local/lib/python3.6/site-packages/sqlalchemy/engine/create.py", line 574, in connect
    return dialect.connect(*cargs, **cparams)
  File "/home/mynguyen/.local/lib/python3.6/site-packages/sqlalchemy/engine/default.py", line 598, in connect
    return self.dbapi.connect(*cargs, **cparams)
  File "/home/mynguyen/.local/lib/python3.6/site-packages/psycopg2/__init__.py", line 122, in connect
    conn = _connect(dsn, connection_factory=connection_factory, **kwasync)
psycopg2.OperationalError: could not connect to server: Connection refused
	Is the server running on host "localhost" (127.0.0.1) and accepting
	TCP/IP connections on port 13490?


The above exception was the direct cause of the following exception:

Traceback (most recent call last):
  File "load_tweets.py", line 345, in <module>
    connection = engine.connect()
  File "/home/mynguyen/.local/lib/python3.6/site-packages/sqlalchemy/engine/base.py", line 3325, in connect
    return self._connection_cls(self, close_with_result=close_with_result)
  File "/home/mynguyen/.local/lib/python3.6/site-packages/sqlalchemy/engine/base.py", line 96, in __init__
    else engine.raw_connection()
  File "/home/mynguyen/.local/lib/python3.6/site-packages/sqlalchemy/engine/base.py", line 3404, in raw_connection
    return self._wrap_pool_connect(self.pool.connect, _connection)
  File "/home/mynguyen/.local/lib/python3.6/site-packages/sqlalchemy/engine/base.py", line 3375, in _wrap_pool_connect
    e, dialect, self
  File "/home/mynguyen/.local/lib/python3.6/site-packages/sqlalchemy/engine/base.py", line 2209, in _handle_dbapi_exception_noconnection
    sqlalchemy_exception, with_traceback=exc_info[2], from_=e
  File "/home/mynguyen/.local/lib/python3.6/site-packages/sqlalchemy/util/compat.py", line 211, in raise_
    raise exception
  File "/home/mynguyen/.local/lib/python3.6/site-packages/sqlalchemy/engine/base.py", line 3371, in _wrap_pool_connect
    return fn()
  File "/home/mynguyen/.local/lib/python3.6/site-packages/sqlalchemy/pool/base.py", line 327, in connect
    return _ConnectionFairy._checkout(self)
  File "/home/mynguyen/.local/lib/python3.6/site-packages/sqlalchemy/pool/base.py", line 894, in _checkout
    fairy = _ConnectionRecord.checkout(pool)
  File "/home/mynguyen/.local/lib/python3.6/site-packages/sqlalchemy/pool/base.py", line 493, in checkout
    rec = pool._do_get()
  File "/home/mynguyen/.local/lib/python3.6/site-packages/sqlalchemy/pool/impl.py", line 146, in _do_get
    self._dec_overflow()
  File "/home/mynguyen/.local/lib/python3.6/site-packages/sqlalchemy/util/langhelpers.py", line 72, in __exit__
    with_traceback=exc_tb,
  File "/home/mynguyen/.local/lib/python3.6/site-packages/sqlalchemy/util/compat.py", line 211, in raise_
    raise exception
  File "/home/mynguyen/.local/lib/python3.6/site-packages/sqlalchemy/pool/impl.py", line 143, in _do_get
    return self._create_connection()
  File "/home/mynguyen/.local/lib/python3.6/site-packages/sqlalchemy/pool/base.py", line 273, in _create_connection
    return _ConnectionRecord(self)
  File "/home/mynguyen/.local/lib/python3.6/site-packages/sqlalchemy/pool/base.py", line 388, in __init__
    self.__connect()
  File "/home/mynguyen/.local/lib/python3.6/site-packages/sqlalchemy/pool/base.py", line 691, in __connect
    pool.logger.debug("Error on connect(): %s", e)
  File "/home/mynguyen/.local/lib/python3.6/site-packages/sqlalchemy/util/langhelpers.py", line 72, in __exit__
    with_traceback=exc_tb,
  File "/home/mynguyen/.local/lib/python3.6/site-packages/sqlalchemy/util/compat.py", line 211, in raise_
    raise exception
  File "/home/mynguyen/.local/lib/python3.6/site-packages/sqlalchemy/pool/base.py", line 686, in __connect
    self.dbapi_connection = connection = pool._invoke_creator(self)
  File "/home/mynguyen/.local/lib/python3.6/site-packages/sqlalchemy/engine/create.py", line 574, in connect
    return dialect.connect(*cargs, **cparams)
  File "/home/mynguyen/.local/lib/python3.6/site-packages/sqlalchemy/engine/default.py", line 598, in connect
    return self.dbapi.connect(*cargs, **cparams)
  File "/home/mynguyen/.local/lib/python3.6/site-packages/psycopg2/__init__.py", line 122, in connect
    conn = _connect(dsn, connection_factory=connection_factory, **kwasync)
sqlalchemy.exc.OperationalError: (psycopg2.OperationalError) could not connect to server: Connection refused
	Is the server running on host "localhost" (127.0.0.1) and accepting
	TCP/IP connections on port 13490?

(Background on this error at: https://sqlalche.me/e/14/e3q8)
Traceback (most recent call last):
  File "/home/mynguyen/.local/lib/python3.6/site-packages/sqlalchemy/engine/base.py", line 3371, in _wrap_pool_connect
    return fn()
  File "/home/mynguyen/.local/lib/python3.6/site-packages/sqlalchemy/pool/base.py", line 327, in connect
    return _ConnectionFairy._checkout(self)
  File "/home/mynguyen/.local/lib/python3.6/site-packages/sqlalchemy/pool/base.py", line 894, in _checkout
    fairy = _ConnectionRecord.checkout(pool)
  File "/home/mynguyen/.local/lib/python3.6/site-packages/sqlalchemy/pool/base.py", line 493, in checkout
    rec = pool._do_get()
  File "/home/mynguyen/.local/lib/python3.6/site-packages/sqlalchemy/pool/impl.py", line 146, in _do_get
    self._dec_overflow()
  File "/home/mynguyen/.local/lib/python3.6/site-packages/sqlalchemy/util/langhelpers.py", line 72, in __exit__
    with_traceback=exc_tb,
  File "/home/mynguyen/.local/lib/python3.6/site-packages/sqlalchemy/util/compat.py", line 211, in raise_
    raise exception
  File "/home/mynguyen/.local/lib/python3.6/site-packages/sqlalchemy/pool/impl.py", line 143, in _do_get
    return self._create_connection()
  File "/home/mynguyen/.local/lib/python3.6/site-packages/sqlalchemy/pool/base.py", line 273, in _create_connection
    return _ConnectionRecord(self)
  File "/home/mynguyen/.local/lib/python3.6/site-packages/sqlalchemy/pool/base.py", line 388, in __init__
    self.__connect()
  File "/home/mynguyen/.local/lib/python3.6/site-packages/sqlalchemy/pool/base.py", line 691, in __connect
    pool.logger.debug("Error on connect(): %s", e)
  File "/home/mynguyen/.local/lib/python3.6/site-packages/sqlalchemy/util/langhelpers.py", line 72, in __exit__
    with_traceback=exc_tb,
  File "/home/mynguyen/.local/lib/python3.6/site-packages/sqlalchemy/util/compat.py", line 211, in raise_
    raise exception
  File "/home/mynguyen/.local/lib/python3.6/site-packages/sqlalchemy/pool/base.py", line 686, in __connect
    self.dbapi_connection = connection = pool._invoke_creator(self)
  File "/home/mynguyen/.local/lib/python3.6/site-packages/sqlalchemy/engine/create.py", line 574, in connect
    return dialect.connect(*cargs, **cparams)
  File "/home/mynguyen/.local/lib/python3.6/site-packages/sqlalchemy/engine/default.py", line 598, in connect
    return self.dbapi.connect(*cargs, **cparams)
  File "/home/mynguyen/.local/lib/python3.6/site-packages/psycopg2/__init__.py", line 122, in connect
    conn = _connect(dsn, connection_factory=connection_factory, **kwasync)
psycopg2.OperationalError: could not connect to server: Connection refused
	Is the server running on host "localhost" (127.0.0.1) and accepting
	TCP/IP connections on port 13490?


The above exception was the direct cause of the following exception:

Traceback (most recent call last):
  File "load_tweets.py", line 345, in <module>
    connection = engine.connect()
  File "/home/mynguyen/.local/lib/python3.6/site-packages/sqlalchemy/engine/base.py", line 3325, in connect
    return self._connection_cls(self, close_with_result=close_with_result)
  File "/home/mynguyen/.local/lib/python3.6/site-packages/sqlalchemy/engine/base.py", line 96, in __init__
    else engine.raw_connection()
  File "/home/mynguyen/.local/lib/python3.6/site-packages/sqlalchemy/engine/base.py", line 3404, in raw_connection
    return self._wrap_pool_connect(self.pool.connect, _connection)
  File "/home/mynguyen/.local/lib/python3.6/site-packages/sqlalchemy/engine/base.py", line 3375, in _wrap_pool_connect
    e, dialect, self
  File "/home/mynguyen/.local/lib/python3.6/site-packages/sqlalchemy/engine/base.py", line 2209, in _handle_dbapi_exception_noconnection
    sqlalchemy_exception, with_traceback=exc_info[2], from_=e
  File "/home/mynguyen/.local/lib/python3.6/site-packages/sqlalchemy/util/compat.py", line 211, in raise_
    raise exception
  File "/home/mynguyen/.local/lib/python3.6/site-packages/sqlalchemy/engine/base.py", line 3371, in _wrap_pool_connect
    return fn()
  File "/home/mynguyen/.local/lib/python3.6/site-packages/sqlalchemy/pool/base.py", line 327, in connect
    return _ConnectionFairy._checkout(self)
  File "/home/mynguyen/.local/lib/python3.6/site-packages/sqlalchemy/pool/base.py", line 894, in _checkout
    fairy = _ConnectionRecord.checkout(pool)
  File "/home/mynguyen/.local/lib/python3.6/site-packages/sqlalchemy/pool/base.py", line 493, in checkout
    rec = pool._do_get()
  File "/home/mynguyen/.local/lib/python3.6/site-packages/sqlalchemy/pool/impl.py", line 146, in _do_get
    self._dec_overflow()
  File "/home/mynguyen/.local/lib/python3.6/site-packages/sqlalchemy/util/langhelpers.py", line 72, in __exit__
    with_traceback=exc_tb,
  File "/home/mynguyen/.local/lib/python3.6/site-packages/sqlalchemy/util/compat.py", line 211, in raise_
    raise exception
  File "/home/mynguyen/.local/lib/python3.6/site-packages/sqlalchemy/pool/impl.py", line 143, in _do_get
    return self._create_connection()
  File "/home/mynguyen/.local/lib/python3.6/site-packages/sqlalchemy/pool/base.py", line 273, in _create_connection
    return _ConnectionRecord(self)
  File "/home/mynguyen/.local/lib/python3.6/site-packages/sqlalchemy/pool/base.py", line 388, in __init__
    self.__connect()
  File "/home/mynguyen/.local/lib/python3.6/site-packages/sqlalchemy/pool/base.py", line 691, in __connect
    pool.logger.debug("Error on connect(): %s", e)
  File "/home/mynguyen/.local/lib/python3.6/site-packages/sqlalchemy/util/langhelpers.py", line 72, in __exit__
    with_traceback=exc_tb,
  File "/home/mynguyen/.local/lib/python3.6/site-packages/sqlalchemy/util/compat.py", line 211, in raise_
    raise exception
  File "/home/mynguyen/.local/lib/python3.6/site-packages/sqlalchemy/pool/base.py", line 686, in __connect
    self.dbapi_connection = connection = pool._invoke_creator(self)
  File "/home/mynguyen/.local/lib/python3.6/site-packages/sqlalchemy/engine/create.py", line 574, in connect
    return dialect.connect(*cargs, **cparams)
  File "/home/mynguyen/.local/lib/python3.6/site-packages/sqlalchemy/engine/default.py", line 598, in connect
    return self.dbapi.connect(*cargs, **cparams)
  File "/home/mynguyen/.local/lib/python3.6/site-packages/psycopg2/__init__.py", line 122, in connect
    conn = _connect(dsn, connection_factory=connection_factory, **kwasync)
sqlalchemy.exc.OperationalError: (psycopg2.OperationalError) could not connect to server: Connection refused
	Is the server running on host "localhost" (127.0.0.1) and accepting
	TCP/IP connections on port 13490?

(Background on this error at: https://sqlalche.me/e/14/e3q8)
Traceback (most recent call last):
  File "/home/mynguyen/.local/lib/python3.6/site-packages/sqlalchemy/engine/base.py", line 3371, in _wrap_pool_connect
    return fn()
  File "/home/mynguyen/.local/lib/python3.6/site-packages/sqlalchemy/pool/base.py", line 327, in connect
    return _ConnectionFairy._checkout(self)
  File "/home/mynguyen/.local/lib/python3.6/site-packages/sqlalchemy/pool/base.py", line 894, in _checkout
    fairy = _ConnectionRecord.checkout(pool)
  File "/home/mynguyen/.local/lib/python3.6/site-packages/sqlalchemy/pool/base.py", line 493, in checkout
    rec = pool._do_get()
  File "/home/mynguyen/.local/lib/python3.6/site-packages/sqlalchemy/pool/impl.py", line 146, in _do_get
    self._dec_overflow()
  File "/home/mynguyen/.local/lib/python3.6/site-packages/sqlalchemy/util/langhelpers.py", line 72, in __exit__
    with_traceback=exc_tb,
  File "/home/mynguyen/.local/lib/python3.6/site-packages/sqlalchemy/util/compat.py", line 211, in raise_
    raise exception
  File "/home/mynguyen/.local/lib/python3.6/site-packages/sqlalchemy/pool/impl.py", line 143, in _do_get
    return self._create_connection()
  File "/home/mynguyen/.local/lib/python3.6/site-packages/sqlalchemy/pool/base.py", line 273, in _create_connection
    return _ConnectionRecord(self)
  File "/home/mynguyen/.local/lib/python3.6/site-packages/sqlalchemy/pool/base.py", line 388, in __init__
    self.__connect()
  File "/home/mynguyen/.local/lib/python3.6/site-packages/sqlalchemy/pool/base.py", line 691, in __connect
    pool.logger.debug("Error on connect(): %s", e)
  File "/home/mynguyen/.local/lib/python3.6/site-packages/sqlalchemy/util/langhelpers.py", line 72, in __exit__
    with_traceback=exc_tb,
  File "/home/mynguyen/.local/lib/python3.6/site-packages/sqlalchemy/util/compat.py", line 211, in raise_
    raise exception
  File "/home/mynguyen/.local/lib/python3.6/site-packages/sqlalchemy/pool/base.py", line 686, in __connect
    self.dbapi_connection = connection = pool._invoke_creator(self)
  File "/home/mynguyen/.local/lib/python3.6/site-packages/sqlalchemy/engine/create.py", line 574, in connect
    return dialect.connect(*cargs, **cparams)
  File "/home/mynguyen/.local/lib/python3.6/site-packages/sqlalchemy/engine/default.py", line 598, in connect
    return self.dbapi.connect(*cargs, **cparams)
  File "/home/mynguyen/.local/lib/python3.6/site-packages/psycopg2/__init__.py", line 122, in connect
    conn = _connect(dsn, connection_factory=connection_factory, **kwasync)
psycopg2.OperationalError: could not connect to server: Connection refused
	Is the server running on host "localhost" (127.0.0.1) and accepting
	TCP/IP connections on port 13490?


The above exception was the direct cause of the following exception:

Traceback (most recent call last):
  File "load_tweets.py", line 345, in <module>
    connection = engine.connect()
  File "/home/mynguyen/.local/lib/python3.6/site-packages/sqlalchemy/engine/base.py", line 3325, in connect
    return self._connection_cls(self, close_with_result=close_with_result)
  File "/home/mynguyen/.local/lib/python3.6/site-packages/sqlalchemy/engine/base.py", line 96, in __init__
    else engine.raw_connection()
  File "/home/mynguyen/.local/lib/python3.6/site-packages/sqlalchemy/engine/base.py", line 3404, in raw_connection
    return self._wrap_pool_connect(self.pool.connect, _connection)
  File "/home/mynguyen/.local/lib/python3.6/site-packages/sqlalchemy/engine/base.py", line 3375, in _wrap_pool_connect
    e, dialect, self
  File "/home/mynguyen/.local/lib/python3.6/site-packages/sqlalchemy/engine/base.py", line 2209, in _handle_dbapi_exception_noconnection
    sqlalchemy_exception, with_traceback=exc_info[2], from_=e
  File "/home/mynguyen/.local/lib/python3.6/site-packages/sqlalchemy/util/compat.py", line 211, in raise_
    raise exception
  File "/home/mynguyen/.local/lib/python3.6/site-packages/sqlalchemy/engine/base.py", line 3371, in _wrap_pool_connect
    return fn()
  File "/home/mynguyen/.local/lib/python3.6/site-packages/sqlalchemy/pool/base.py", line 327, in connect
    return _ConnectionFairy._checkout(self)
  File "/home/mynguyen/.local/lib/python3.6/site-packages/sqlalchemy/pool/base.py", line 894, in _checkout
    fairy = _ConnectionRecord.checkout(pool)
  File "/home/mynguyen/.local/lib/python3.6/site-packages/sqlalchemy/pool/base.py", line 493, in checkout
    rec = pool._do_get()
  File "/home/mynguyen/.local/lib/python3.6/site-packages/sqlalchemy/pool/impl.py", line 146, in _do_get
    self._dec_overflow()
  File "/home/mynguyen/.local/lib/python3.6/site-packages/sqlalchemy/util/langhelpers.py", line 72, in __exit__
    with_traceback=exc_tb,
  File "/home/mynguyen/.local/lib/python3.6/site-packages/sqlalchemy/util/compat.py", line 211, in raise_
    raise exception
  File "/home/mynguyen/.local/lib/python3.6/site-packages/sqlalchemy/pool/impl.py", line 143, in _do_get
    return self._create_connection()
  File "/home/mynguyen/.local/lib/python3.6/site-packages/sqlalchemy/pool/base.py", line 273, in _create_connection
    return _ConnectionRecord(self)
  File "/home/mynguyen/.local/lib/python3.6/site-packages/sqlalchemy/pool/base.py", line 388, in __init__
    self.__connect()
  File "/home/mynguyen/.local/lib/python3.6/site-packages/sqlalchemy/pool/base.py", line 691, in __connect
    pool.logger.debug("Error on connect(): %s", e)
  File "/home/mynguyen/.local/lib/python3.6/site-packages/sqlalchemy/util/langhelpers.py", line 72, in __exit__
    with_traceback=exc_tb,
  File "/home/mynguyen/.local/lib/python3.6/site-packages/sqlalchemy/util/compat.py", line 211, in raise_
    raise exception
  File "/home/mynguyen/.local/lib/python3.6/site-packages/sqlalchemy/pool/base.py", line 686, in __connect
    self.dbapi_connection = connection = pool._invoke_creator(self)
  File "/home/mynguyen/.local/lib/python3.6/site-packages/sqlalchemy/engine/create.py", line 574, in connect
    return dialect.connect(*cargs, **cparams)
  File "/home/mynguyen/.local/lib/python3.6/site-packages/sqlalchemy/engine/default.py", line 598, in connect
    return self.dbapi.connect(*cargs, **cparams)
  File "/home/mynguyen/.local/lib/python3.6/site-packages/psycopg2/__init__.py", line 122, in connect
    conn = _connect(dsn, connection_factory=connection_factory, **kwasync)
sqlalchemy.exc.OperationalError: (psycopg2.OperationalError) could not connect to server: Connection refused
	Is the server running on host "localhost" (127.0.0.1) and accepting
	TCP/IP connections on port 13490?

(Background on this error at: https://sqlalche.me/e/14/e3q8)
Command exited with non-zero status 10
3.91user 0.60system 0:00.80elapsed 559%CPU (0avgtext+0avgdata 43360maxresident)k
608inputs+2208outputs (5major+153824minor)pagefaults 0swaps
